Workbook

Sheet ENTRIES
A1: AACPS County Championships 9/29 @ Compass Pointe 8:30am PAIRINGS
A2: First and Last Name | B2: Grade | C2: School | D2: M/F
A3: William Meyer | B3: 11 | C3: Annapolis | D3: M
A4: Evan Lyman | B4: 11 | C4: Annapolis | D4: M
A5: Drew Shallcross | B5: 12 | C5: Annapolis | D5: M
A6: Daniel Capo | B6: 12 | C6: Annapolis | D6: M
A7: Colt Jett | B7: 12 | C7: Annapolis | D7: M
A8: Lizzy Thibodeau | B8: 9 | C8: Annapolis | D8: F
A9: Chase Fortescue | B9: 12 | C9: Arundel | D9: M
A10: Aidan Pelkey | B10: 11 | C10: Arundel | D10: M
A11: Devin Crabbe | B11: 11 | C11: Arundel | D11: M
A12: Luke Gamble | B12: 12 | C12: Arundel | D12: M
A13: Maxwell Morgan | B13: 11 | C13: Arundel | D13: M
A14: Ava Shay | B14: 12 | C14: Arundel | D14: F
... A32: Bryn Calicoat | B32: 11 | C32: Chesapeake | D32: F
C33: Chesapeake
A34: Ty Swann | B34: 11 | C34: Crofton | D34: M
A35: Ben Cunningham | B35: 12 | C35: Crofton | D35: M
A36: Gianni Gallow | B36: 12 | C36: Crofton | D36: M
A37: Charlie Ward | B37: 9 | C37: Crofton | D37: M
A38: Nate Fine | B38: 12 | C38: Crofton | D38: M
A39: Ethan Kelly | B39: 12 | C39: Crofton | D39: M
A40: Marissa Liverpool | B40: 11 | C40: Crofton | D40: F
A41: Claire Kerley | B41: 10 | C41: Crofton | D41: F
A42: Molly Boyle | B42: 9 | C42: Crofton | D42: F
A43: Emily Huus | B43: 12 | C43: Crofton | D43: F
A44: Rhyan Arciaga | B44: 10 | C44: Chesapeake Science | D44: M
A45: Dylan Morgan | B45: 11 | C45: Chesapeake Science
A46: Devon Myers | B46: 9 | C46: Glen Burnie | D46: M
A47: Liam Hontz | B47: 12 | C47: North County | D47: M
A48: James Posey | B48: 10 | C48: North County | D48: M
A49: Griffin Boritz | B49: 9 | C49: North County | D49: M
A50: Ethan Price | B50: 10 | C50: North County | D50: M
A51: Alec Behegan | B51: 12 | C51: North County | D51: M
A52: Nate Alimo | B52: 12 | C52: North County | D52: M
A53: Kaden Wyatt | B53: 11 | C53: Northeast | D53: M
A54: Mason Kolodziejski | B54: 12 | C54: Northeast | D54: M
A55: Ethan Goughenour | B55: 11 | C55: Old Mill | D55: M
A56: Reece Miguel | B56: 12 | C56: Severn Run | D56: M
A57: Garrett James | B57: 10 | C57: Severn Run | D57: M
...

Sheet PAIRINGS
A1: AACPS County Championships 9/29 @ Compass Pointe 8:30am PAIRINGS | H1: OFFICIAL SCORING BY HOLE
A2: Start | B2: First and Last Name | C2: Grade | D2: School | E2: M/F | F2: Marshal | H2: 1 | I2: 2 | J2: 3 | K2: 4 | L2: 5 | M2: 6 | N2: 7 | O2: 8 | P2: 9 | Q2: OUT | R2: 10 | S2: 11 | T2: 12 | U2: 13 | V2: 14 | W2: 15 | X2: 16 | Y2: 17 | Z2: 18 | AA2: IN | AB2: TOT
A3: 1A | B3: Ty Swann | C3: 11 | D3: Crofton | E3: M | F3: Schlossberg (SR) | Q3: =SUM(H3:P3) -> 0 | AA3: =SUM(R3:Z3) -> 0 | AB3: =Q3+AA3 -> 0
B4: Davis Balderston | C4: 9 | D4: Severna Park | E4: M | Q4: =SUM(H4:P4) -> 0 | AA4: =SUM(R4:Z4) -> 0 | AB4: =Q4+AA4 -> 0
B5: James Jonker | C5: 12 | D5: Broadneck | E5: M | Q5: =SUM(H5:P5) -> 0 | AA5: =SUM(R5:Z5) -> 0 | AB5: =Q5+AA5 -> 0
B6: Gavin Allison | C6: 12 | D6: Chesapeake | E6: M | Q6: =SUM(H6:P6) -> 0 | AA6: =SUM(R6:Z6) -> 0 | AB6: =Q6+AA6 -> 0
A7: 1B | B7: Ewan Ivey | C7: 11 | D7: Southern | E7: M | F7: Snyder (CR) | Q7: =SUM(H7:P7) -> 0 | AA7: =SUM(R7:Z7) -> 0 | AB7: =Q7+AA7 -> 0
B8: Chase Connell | C8: 10 | D8: Severna Park | E8: M | Q8: =SUM(H8:P8) -> 0 | AA8: =SUM(R8:Z8) -> 0 | AB8: =Q8+AA8 -> 0
B9: Michael Peterson | C9: 11 | D9: Broadneck | E9: M | Q9: =SUM(H9:P9) -> 0 | AA9: =SUM(R9:Z9) -> 0 | AB9: =Q9+AA9 -> 0
B10: Alan Higgins | C10: 12 | D10: Chesapeake | E10: M | Q10: =SUM(H10:P10) -> 0 | AA10: =SUM(R10:Z10) -> 0 | AB10: =Q10+AA10 -> 0
A11: 18A | B11: Micah Gossard | C11: 10 | D11: Broadneck | E11: M | F11: Brobst (AR) | Q11: =SUM(H11:P11) -> 0 | AA11: =SUM(R11:Z11) -> 0 | AB11: =Q11+AA11 -> 0
B12: CJ Burke | C12: 12 | D12: South River | E12: M | Q12: =SUM(H12:P12) -> 0 | AA12: =SUM(R12:Z12) -> 0 | AB12: =Q12+AA12 -> 0
B13: Chase Youmans | C13: 12 | D13: Southern | E13: M | Q13: =SUM(H13:P13) -> 0 | AA13: =SUM(R13:Z13) -> 0 | AB13: =Q13+AA13 -> 0
B14: Jack Peery | C14: 11 | D14: Severna Park | E14: M | Q14: =SUM(H14:P14) -> 0 | AA14: =SUM(R14:Z14) -> 0 | AB14: =Q14+AA14 -> 0
A15: 18B | B15: Max Harada | C15: 12 | D15: Broadneck | E15: M | F15: J Dean (SP) | Q15: =SUM(H15:P15) -> 0 | AA15: =SUM(R15:Z15) -> 0 | AB15: =Q15+AA15 -> 0
B16: Chase Fortescue | C16: 12 | D16: Arundel | E16: M | Q16: =SUM(H16:P16) -> 0 | AA16: =SUM(R16:Z16) -> 0 | AB16: =Q16+AA16 -> 0
B17: Bryce Crandell | C17: 11 | D17: Southern | E17: M | Q17: =SUM(H17:P17) -> 0 | AA17: =SUM(R17:Z17) -> 0 | AB17: =Q17+AA17 -> 0
B18: Cooper Barnes | C18: 12 | D18: Chesapeake | E18: M | Q18: =SUM(H18:P18) -> 0 | AA18: =SUM(R18:Z18) -> 0 | AB18: =Q18+AA18 -> 0
A19: 17A | B19: Owen Moon | C19: 12 | D19: Southern | E19: M | F19: Merkel (OM) | Q19: =SUM(H19:P19) -> 0 | AA19: =SUM(R19:Z19) -> 0 | AB19: =Q19+AA19 -> 0
B20: Liam Finnegan | C20: 10 | D20: Chesapeake | E20: M | Q20: =SUM(H20:P20) -> 0 | AA20: =SUM(R20:Z20) -> 0 | AB20: =Q20+AA20 -> 0
B21: Ben Cunningham | C21: 12 | D21: Crofton | E21: M | Q21: =SUM(H21:P21) -> 0 | AA21: =SUM(R21:Z21) -> 0 | AB21: =Q21+AA21 -> 0
B22: Chris Jenkins | C22: 11 | D22: Severna Park | E22: M | Q22: =SUM(H22:P22) -> 0 | AA22: =SUM(R22:Z22) -> 0 | AB22: =Q22+AA22 -> 0
A23: 17B | B23: Brody McCafferty | C23: 11 | D23: Southern | E23: M | F23: Reid (NE) | Q23: =SUM(H23:P23) -> 0 | AA23: =SUM(R23:Z23) -> 0 | AB23: =Q23+AA23 -> 0
B24: Nate Fine | C24: 12 | D24: Crofton | E24: M | Q24: =SUM(H24:P24) -> 0 | AA24: =SUM(R24:Z24) -> 0 | AB24: =Q24+AA24 -> 0
B25: KJ Flanagan | C25: 11 | D25: Severna Park | E25: M | Q25: =SUM(H25:P25) -> 0 | AA25: =SUM(R25:Z25) -> 0 | AB25: =Q25+AA25 -> 0
B26: William Meyer | C26: 11 | D26: Annapolis | E26: M | Q26: =SUM(H26:P26) -> 0 | AA26: =SUM(R26:Z26) -> 0 | AB26: =Q26+AA26 -> 0
A27: 16A | B27: Luca Vendemia | C27: 9 | D27: Southern | E27: M | F27: Levine (AN) | Q27: =SUM(H27:P27) -> 0 | AA27: =SUM(R27:Z27) -> 0 | AB27: =Q27+AA27 -> 0
B28: Gianni Gallow | C28: 12 | D28: Crofton | E28: M | Q28: =SUM(H28:P28) -> 0 | AA28: =SUM(R28:Z28) -> 0 | AB28: =Q28+AA28 -> 0
B29: Colin Barry | C29: 9 | D29: Severna Park | E29: M | Q29: =SUM(H29:P29) -> 0 | AA29: =SUM(R29:Z29) -> 0 | AB29: =Q29+AA29 -> 0
B30: Paolo Maggio | C30: 12 | D30: South River | E30: M | Q30: =SUM(H30:P30) -> 0 | AA30: =SUM(R30:Z30) -> 0 | AB30: =Q30+AA30 -> 0
A31: 16B | B31: Evan Lyman | C31: 11 | D31: Annapolis | E31: M | F31: Jocius (SO) | Q31: =SUM(H31:P31) -> 0 | AA31: =SUM(R31:Z31) -> 0 | AB31: =Q31+AA31 -> 0
B32: Charlie Ward | C32: 9 | D32: Crofton | E32: M | Q32: =SUM(H32:P32) -> 0 | AA32: =SUM(R32:Z32) -> 0 | AB32: =Q32+AA32 -> 0
B33: Nathan Reil | C33: 12 | D33: Chesapeake | E33: M | Q33: =SUM(H33:P33) -> 0 | AA33: =SUM(R33:Z33) -> 0 | AB33: =Q33+AA33 -> 0
B34: Chris Mahnke | C34: 10 | D34: Severn Run | E34: M | Q34: =SUM(H34:P34) -> 0 | AA34: =SUM(R34:Z34) -> 0 | AB34: =Q34+AA34 -> 0
A35: 15A | B35: Ethan Kelly | C35: 12 | D35: Crofton | E35: M | F35: Schmidt (GB) | Q35: =SUM(H35:P35) -> 0 | AA35: =SUM(R35:Z35) -> 0 | AB35: =Q35+AA35 -> 0
B36: Mason Bombard | C36: 12 | D36: Chesapeake | E36: M
B37: Aidan Pelkey | C37: 11 | D37: Arundel | E37: M
B38: James Posey | C38: 10 | D38: North County | E38: M
A39: 15B | B39: Garrett James | C39: 10 | D39: Severn Run | E39: M | F39: Stimaker (BN)
B40: Rhyan Arciaga | C40: 10 | D40: Chesapeake Science | E40: M
...

Sheet 1A
A1: Marshal | B1: Start | C1: AACPS County Championship 9/29 @ Compass Pointe LIVE SCORING
A2: =PAIRINGS!F3 -> Schlossberg (SR) | B2: =PAIRINGS!A3 -> 1A
A4: Name | B4: School | C4: 1 | D4: 2 | E4: 3 | F4: 4 | G4: 5 | H4: 6 | I4: 7 | J4: 8 | K4: 9 | L4: IN
A6: =PAIRINGS!B3 -> Ty Swann | B6: =PAIRINGS!D3 -> Crofton | C6: 5 | D6: 3 | E6: 4 | F6: 3 | G6: 4 | H6: 4 | I6: 5 | J6: 4 | K6: 5 | L6: =SUM(C6:K6) -> 37
A7: =PAIRINGS!B4 -> Davis Balderston | B7: =PAIRINGS!D4 -> Severna Park | C7: 5 | D7: 3 | E7: 4 | F7: 3 | G7: 4 | H7: 3 | I7: 5 | J7: 4 | K7: 3 | L7: =SUM(C7:K7) -> 34
A8: =PAIRINGS!B5 -> James Jonker | B8: =PAIRINGS!D5 -> Broadneck | C8: 5 | D8: 3 | E8: 3 | F8: 3 | G8: 5 | H8: 5 | I8: 4 | J8: 4 | K8: 4 | L8: =SUM(C8:K8) -> 36
A9: =PAIRINGS!B6 -> Gavin Allison | B9: =PAIRINGS!D6 -> Chesapeake | C9: 5 | D9: 3 | E9: 5 | F9: 4 | G9: 4 | H9: 5 | I9: 5 | J9: 6 | K9: 7 | L9: =SUM(C9:K9) -> 44
A11: Name | B11: School | C11: 10 | D11: 11 | E11: 12 | F11: 13 | G11: 14 | H11: 15 | I11: 16 | J11: 17 | K11: 18 | L11: OUT | M11: TOTAL
A13: =A6 -> Ty Swann | B13: =B6 -> Crofton | C13: 5 | D13: 3 | E13: 4 | F13: 3 | G13: 6 | H13: 4 | I13: 5 | L13: =SUM(C13:K13) -> 30 | M13: =SUM(L6 + L13) -> 67
A14: =A7 -> Davis Balderston | B14: =B7 -> Severna Park | C14: 4 | D14: 3 | E14: 5 | F14: 3 | G14: 4 | H14: 4 | I14: 6 | L14: =SUM(C14:K14) -> 29 | M14: =SUM(L7 + L14) -> 63
A15: =A8 -> James Jonker | B15: =B8 -> Broadneck | C15: 4 | D15: 3 | E15: 5 | F15: 3 | G15: 4 | H15: 4 | I15: 5 | L15: =SUM(C15:K15) -> 28 | M15: =SUM(L8 + L15) -> 64
A16: =A9 -> Gavin Allison | B16: =B9 -> Chesapeake | C16: 4 | D16: 4 | E16: 4 | F16: 3 | G16: 5 | H16: 3 | I16: 4 | L16: =SUM(C16:K16) -> 27 | M16: =SUM(L9 + L16) -> 71

Sheet 1B
A1: Marshal | B1: Start | C1: AACPS County Championship 9/29 @ Compass Pointe LIVE SCORING
A2: =PAIRINGS!F7 -> Snyder (CR) | B2: =PAIRINGS!A7 -> 1B
A4: Name | B4: School | C4: 1 | D4: 2 | E4: 3 | F4: 4 | G4: 5 | H4: 6 | I4: 7 | J4: 8 | K4: 9 | L4: IN
A6: =PAIRINGS!B7 -> Ewan Ivey | B6: =PAIRINGS!D7 -> Southern | C6: 6 | D6: 3 | E6: 4 | F6: 4 | G6: 5 | H6: 4 | I6: 5 | J6: 4 | K6: 5 | L6: =SUM(C6:K6) -> 40
A7: =PAIRINGS!B8 -> Chase Connell | B7: =PAIRINGS!D8 -> Severna Park | C7: 5 | D7: 3 | E7: 4 | F7: 3 | G7: 4 | H7: 4 | I7: 6 | J7: 4 | K7: 3 | L7: =SUM(C7:K7) -> 36
A8: =PAIRINGS!B9 -> Michael Peterson | B8: =PAIRINGS!D9 -> Broadneck | C8: 5 | D8: 3 | E8: 5 | F8: 5 | G8: 7 | H8: 4 | I8: 5 | J8: 4 | K8: 4 | L8: =SUM(C8:K8) -> 42
A9: =PAIRINGS!B10 -> Alan Higgins | B9: =PAIRINGS!D10 -> Chesapeake | C9: 5 | D9: 4 | E9: 5 | F9: 4 | G9: 4 | H9: 6 | I9: 4 | J9: 5 | K9: 5 | L9: =SUM(C9:K9) -> 42
A11: Name | B11: School | C11: 10 | D11: 11 | E11: 12 | F11: 13 | G11: 14 | H11: 15 | I11: 16 | J11: 17 | K11: 18 | L11: OUT | M11: TOTAL
A13: =A6 -> Ewan Ivey | B13: =B6 -> Southern | C13: 5 | D13: 4 | E13: 5 | F13: 4 | G13: 5 | H13: 3 | L13: =SUM(C13:K13) -> 26 | M13: =SUM(L6 + L13) -> 66
A14: =A7 -> Chase Connell | B14: =B7 -> Severna Park | C14: 5 | D14: 3 | E14: 5 | F14: 2 | G14: 5 | H14: 4 | L14: =SUM(C14:K14) -> 24 | M14: =SUM(L7 + L14) -> 60
A15: =A8 -> Michael Peterson | B15: =B8 -> Broadneck | C15: 4 | D15: 5 | E15: 6 | F15: 3 | G15: 5 | H15: 3 | L15: =SUM(C15:K15) -> 26 | M15: =SUM(L8 + L15) -> 68
A16: =A9 -> Alan Higgins | B16: =B9 -> Chesapeake | C16: 4 | D16: 3 | E16: 5 | F16: 5 | G16: 6 | H16: 8 | L16: =SUM(C16:K16) -> 31 | M16: =SUM(L9 + L16) -> 73

Sheet 18A
A1: Marshal | B1: Start | C1: AACPS County Championship 9/29 @ Compass Pointe LIVE SCORING
A2: =PAIRINGS!F11 -> Brobst (AR) | B2: =PAIRINGS!A11 -> 18A
A4: Name | B4: School | C4: 1 | D4: 2 | E4: 3 | F4: 4 | G4: 5 | H4: 6 | I4: 7 | J4: 8 | K4: 9 | L4: IN
A6: =PAIRINGS!B11 -> Micah Gossard | B6: =PAIRINGS!D11 -> Broadneck | C6: 5 | D6: 3 | E6: 5 | F6: 4 | G6: 5 | H6: 5 | I6: 6 | J6: 4 | K6: 4 | L6: =SUM(C6:K6) -> 41
A7: =PAIRINGS!B12 -> CJ Burke | B7: =PAIRINGS!D12 -> South River | C7: 6 | D7: 5 | E7: 5 | F7: 4 | G7: 5 | H7: 5 | I7: 6 | J7: 5 | K7: 3 | L7: =SUM(C7:K7) -> 44
A8: =PAIRINGS!B13 -> Chase Youmans | B8: =PAIRINGS!D13 -> Southern | C8: 7 | D8: 3 | E8: 7 | F8: 4 | G8: 6 | H8: 6 | I8: 7 | J8: 4 | K8: 4 | L8: =SUM(C8:K8) -> 48
A9: =PAIRINGS!B14 -> Jack Peery | B9: =PAIRINGS!D14 -> Severna Park | C9: 5 | D9: 7 | E9: 4 | F9: 3 | G9: 5 | H9: 7 | I9: 6 | J9: 4 | K9: 5 | L9: =SUM(C9:K9) -> 46
A11: Name | B11: School | C11: 10 | D11: 11 | E11: 12 | F11: 13 | G11: 14 | H11: 15 | I11: 16 | J11: 17 | K11: 18 | L11: OUT | M11: TOTAL
A13: =A6 -> Micah Gossard | B13: =B6 -> Broadneck | C13: 4 | D13: 3 | E13: 7 | F13: 4 | G13: 4 | H13: 4 | K13: 4 | L13: =SUM(C13:K13) -> 30 | M13: =SUM(L6 + L13) -> 71
A14: =A7 -> CJ Burke | B14: =B7 -> South River | C14: 5 | D14: 3 | E14: 6 | F14: 3 | G14: 6 | H14: 4 | K14: 3 | L14: =SUM(C14:K14) -> 30 | M14: =SUM(L7 + L14) -> 74
A15: =A8 -> Chase Youmans | B15: =B8 -> Southern | C15: 7 | D15: 5 | E15: 5 | F15: 6 | G15: 6 | H15: 4 | K15: 5 | L15: =SUM(C15:K15) -> 38 | M15: =SUM(L8 + L15) -> 86
A16: =A9 -> Jack Peery | B16: =B9 -> Severna Park | C16: 7 | D16: 3 | E16: 6 | F16: 6 | G16: 6 | H16: 4 | K16: 3 | L16: =SUM(C16:K16) -> 35 | M16: =SUM(L9 + L16) -> 81

Sheet 18B
A1: Marshal | B1: Start | C1: AACPS County Championship 9/29 @ Compass Pointe LIVE SCORING
A2: =PAIRINGS!F15 -> J Dean (SP) | B2: =PAIRINGS!A15 -> 18B
A4: Name | B4: School | C4: 1 | D4: 2 | E4: 3 | F4: 4 | G4: 5 | H4: 6 | I4: 7 | J4: 8 | K4: 9 | L4: IN
A6: =PAIRINGS!B15 -> Max Harada | B6: =PAIRINGS!D15 -> Broadneck | C6: 9 | D6: 3 | E6: 9 | F6: 3 | G6: 5 | H6: 5 | I6: 6 | J6: 4 | K6: 5 | L6: =SUM(C6:K6) -> 49
A7: =PAIRINGS!B16 -> Chase Fortescue | B7: =PAIRINGS!D16 -> Arundel | C7: 6 | D7: 5 | E7: 5 | F7: 4 | G7: 8 | H7: 5 | I7: 6 | J7: 5 | K7: 5 | L7: =SUM(C7:K7) -> 49
A8: =PAIRINGS!B17 -> Bryce Crandell | B8: =PAIRINGS!D17 -> Southern | C8: 6 | D8: 5 | E8: 7 | F8: 7 | G8: 4 | H8: 6 | I8: 9 | J8: 4 | K8: 4 | L8: =SUM(C8:K8) -> 52
A9: =PAIRINGS!B18 -> Cooper Barnes | B9: =PAIRINGS!D18 -> Chesapeake | C9: 6 | D9: 3 | E9: 6 | F9: 4 | G9: 4 | H9: 7 | I9: 5 | J9: 5 | K9: 5 | L9: =SUM(C9:K9) -> 45
A11: Name | B11: School | C11: 10 | D11: 11 | E11: 12 | F11: 13 | G11: 14 | H11: 15 | I11: 16 | J11: 17 | K11: 18 | L11: OUT | M11: TOTAL
A13: =A6 -> Max Harada | B13: =B6 -> Broadneck | C13: 4 | D13: 4 | E13: 5 | F13: 4 | G13: 5 | K13: 5 | L13: =SUM(C13:K13) -> 27 | M13: =SUM(L6 + L13) -> 76
A14: =A7 -> Chase Fortescue | B14: =B7 -> Arundel | C14: 6 | D14: 2 | E14: 6 | F14: 2 | G14: 6 | K14: 5 | L14: =SUM(C14:K14) -> 27 | M14: =SUM(L7 + L14) -> 76
A15: =A8 -> Bryce Crandell | B15: =B8 -> Southern | C15: 4 | D15: 3 | E15: 6 | F15: 4 | G15: 6 | K15: 7 | L15: =SUM(C15:K15) -> 30 | M15: =SUM(L8 + L15) -> 82
A16: =A9 -> Cooper Barnes | B16: =B9 -> Chesapeake | C16: 7 | D16: 4 | E16: 7 | F16: 4 | G16: 4 | K16: 5 | L16: =SUM(C16:K16) -> 31 | M16: =SUM(L9 + L16) -> 76

Sheet 17A
A1: Marshal | B1: Start | C1: AACPS County Championship 9/29 @ Compass Pointe LIVE SCORING
A2: =PAIRINGS!F19 -> Merkel (OM) | B2: =PAIRINGS!A19 -> 17A
A4: Name | B4: School | C4: 1 | D4: 2 | E4: 3 | F4: 4 | G4: 5 | H4: 6 | I4: 7 | J4: 8 | K4: 9 | L4: IN
A6: =PAIRINGS!B19 -> Owen Moon | B6: =PAIRINGS!D19 -> Southern | C6: 5 | D6: 5 | E6: 4 | F6: 4 | G6: 4 | H6: 3 | I6: 7 | J6: 6 | K6: 4 | L6: =SUM(C6:K6) -> 42
A7: =PAIRINGS!B20 -> Liam Finnegan | B7: =PAIRINGS!D20 -> Chesapeake | C7: 8 | D7: 3 | E7: 5 | F7: 5 | G7: 4 | H7: 7 | I7: 5 | J7: 4 | K7: 4 | L7: =SUM(C7:K7) -> 45
A8: =PAIRINGS!B21 -> Ben Cunningham | B8: =PAIRINGS!D21 -> Crofton | C8: 6 | D8: 3 | E8: 6 | F8: 3 | G8: 4 | H8: 6 | I8: 5 | J8: 6 | K8: 4 | L8: =SUM(C8:K8) -> 43
A9: =PAIRINGS!B22 -> Chris Jenkins | B9: =PAIRINGS!D22 -> Severna Park | C9: 7 | D9: 4 | E9: 5 | F9: 3 | G9: 6 | H9: 5 | I9: 5 | J9: 4 | K9: 6 | L9: =SUM(C9:K9) -> 45
K10: 6
A11: Name | B11: School | C11: 10 | D11: 11 | E11: 12 | F11: 13 | G11: 14 | H11: 15 | I11: 16 | J11: 17 | K11: 18 | L11: OUT | M11: TOTAL
A13: =A6 -> Owen Moon | B13: =B6 -> Southern | C13: 5 | D13: 4 | E13: 6 | F13: 4 | G13: 5 | J13: 4 | K13: 6 | L13: =SUM(C13:K13) -> 34 | M13: =SUM(L6 + L13) -> 76
A14: =A7 -> Liam Finnegan | B14: =B7 -> Chesapeake | C14: 4 | D14: 3 | E14: 5 | F14: 3 | G14: 7 | J14: 4 | K14: 4 | L14: =SUM(C14:K14) -> 30 | M14: =SUM(L7 + L14) -> 75
A15: =A8 -> Ben Cunningham | B15: =B8 -> Crofton | C15: 4 | D15: 3 | E15: 6 | F15: 3 | G15: 6 | J15: 4 | K15: 4 | L15: =SUM(C15:K15) -> 30 | M15: =SUM(L8 + L15) -> 73
A16: =A9 -> Chris Jenkins | B16: =B9 -> Severna Park | C16: 4 | D16: 4 | E16: 6 | F16: 3 | G16: 5 | J16: 5 | K16: 5 | L16: =SUM(C16:K16) -> 32 | M16: =SUM(L9 + L16) -> 77

Sheet 17B
A1: Marshal | B1: Start | C1: AACPS County Championship 9/29 @ Compass Pointe LIVE SCORING
A2: =PAIRINGS!F23 -> Reid (NE) | B2: =PAIRINGS!A23 -> 17B
A4: Name | B4: School | C4: 1 | D4: 2 | E4: 3 | F4: 4 | G4: 5 | H4: 6 | I4: 7 | J4: 8 | K4: 9 | L4: IN
A6: =PAIRINGS!B23 -> Brody McCafferty | B6: =PAIRINGS!D23 -> Southern | C6: 7 | D6: 4 | E6: 6 | F6: 4 | G6: 5 | H6: 6 | I6: 6 | J6: 7 | K6: 4 | L6: =SUM(C6:K6) -> 49
A7: =PAIRINGS!B24 -> Nate Fine | B7: =PAIRINGS!D24 -> Crofton | C7: 5 | D7: 4 | E7: 5 | F7: 5 | G7: 6 | H7: 5 | I7: 5 | J7: 6 | K7: 5 | L7: =SUM(C7:K7) -> 46
A8: =PAIRINGS!B25 -> KJ Flanagan | B8: =PAIRINGS!D25 -> Severna Park | C8: 7 | D8: 3 | E8: 5 | F8: 2 | G8: 4 | H8: 3 | I8: 7 | J8: 5 | K8: 6 | L8: =SUM(C8:K8) -> 42
A9: =PAIRINGS!B26 -> William Meyer | B9: =PAIRINGS!D26 -> Annapolis | C9: 7 | D9: 5 | E9: 5 | F9: 4 | G9: 5 | H9: 6 | I9: 6 | J9: 5 | K9: 3 | L9: =SUM(C9:K9) -> 46
A11: Name | B11: School | C11: 10 | D11: 11 | E11: 12 | F11: 13 | G11: 14 | H11: 15 | I11: 16 | J11: 17 | K11: 18 | L11: OUT | M11: TOTAL
A13: =A6 -> Brody McCafferty | B13: =B6 -> Southern | C13: 6 | D13: 5 | E13: 6 | F13: 3 | J13: 5 | K13: 5 | L13: =SUM(C13:K13) -> 30 | M13: =SUM(L6 + L13) -> 79
A14: =A7 -> Nate Fine | B14: =B7 -> Crofton | C14: 6 | D14: 3 | E14: 8 | F14: 3 | J14: 5 | K14: 4 | L14: =SUM(C14:K14) -> 29 | M14: =SUM(L7 + L14) -> 75
A15: =A8 -> KJ Flanagan | B15: =B8 -> Severna Park | C15: 4 | D15: 4 | E15: 6 | F15: 3 | J15: 5 | K15: 5 | L15: =SUM(C15:K15) -> 27 | M15: =SUM(L8 + L15) -> 69
A16: =A9 -> William Meyer | B16: =B9 -> Annapolis | C16: 4 | D16: 4 | E16: 6 | F16: 4 | J16: 6 | K16: 4 | L16: =SUM(C16:K16) -> 28 | M16: =SUM(L9 + L16) -> 74

Sheet 16A
A1: Marshal | B1: Start | C1: AACPS County Championship 9/29 @ Compass Pointe LIVE SCORING
A2: =PAIRINGS!F27 -> Levine (AN) | B2: =PAIRINGS!A27 -> 16A
A4: Name | B4: School | C4: 1 | D4: 2 | E4: 3 | F4: 4 | G4: 5 | H4: 6 | I4: 7 | J4: 8 | K4: 9 | L4: IN
A6: =PAIRINGS!B27 -> Luca Vendemia | B6: =PAIRINGS!D27 -> Southern | C6: 6 | D6: 5 | E6: 4 | F6: 7 | G6: 4 | H6: 4 | I6: 6 | J6: 4 | K6: 4 | L6: =SUM(C6:K6) -> 44
A7: =PAIRINGS!B28 -> Gianni Gallow | B7: =PAIRINGS!D28 -> Crofton | C7: 5 | D7: 4 | E7: 4 | F7: 3 | G7: 7 | H7: 6 | I7: 6 | J7: 4 | K7: 5 | L7: =SUM(C7:K7) -> 44
A8: =PAIRINGS!B29 -> Colin Barry | B8: =PAIRINGS!D29 -> Severna Park | C8: 7 | D8: 5 | E8: 5 | F8: 3 | G8: 3 | H8: 5 | I8: 6 | J8: 5 | K8: 5 | L8: =SUM(C8:K8) -> 44
A9: =PAIRINGS!B30 -> Paolo Maggio | B9: =PAIRINGS!D30 -> South River | C9: 6 | D9: 4 | E9: 5 | F9: 3 | G9: 4 | H9: 4 | I9: 6 | J9: 6 | K9: 4 | L9: =SUM(C9:K9) -> 42
A11: Name | B11: School | C11: 10 | D11: 11 | E11: 12 | F11: 13 | G11: 14 | H11: 15 | I11: 16 | J11: 17 | K11: 18 | L11: OUT | M11: TOTAL
A13: =A6 -> Luca Vendemia | B13: =B6 -> Southern | C13: 5 | D13: 2 | I13: 8 | J13: 5 | K13: 3 | L13: =SUM(C13:K13) -> 23 | M13: =SUM(L6 + L13) -> 67
A14: =A7 -> Gianni Gallow | B14: =B7 -> Crofton | C14: 6 | D14: 5 | I14: 8 | J14: 5 | K14: 6 | L14: =SUM(C14:K14) -> 30 | M14: =SUM(L7 + L14) -> 74
A15: =A8 -> Colin Barry | B15: =B8 -> Severna Park | C15: 4 | D15: 4 | I15: 6 | J15: 5 | K15: 4 | L15: =SUM(C15:K15) -> 23 | M15: =SUM(L8 + L15) -> 67
A16: =A9 -> Paolo Maggio | B16: =B9 -> South River | C16: 4 | D16: 3 | I16: 8 | J16: 8 | K16: 5 | L16: =SUM(C16:K16) -> 28 | M16: =SUM(L9 + L16) -> 70

Sheet 16B
A1: Marshal | B1: Start | C1: AACPS County Championship 9/29 @ Compass Pointe LIVE SCORING
A2: =PAIRINGS!F31 -> Jocius (SO) | B2: =PAIRINGS!A31 -> 16B
A4: Name | B4: School | C4: 1 | D4: 2 | E4: 3 | F4: 4 | G4: 5 | H4: 6 | I4: 7 | J4: 8 | K4: 9 | L4: IN
E5: 6
A6: =PAIRINGS!B31 -> Evan Lyman | B6: =PAIRINGS!D31 -> Annapolis | C6: 7 | D6: 6 | E6: 6 | F6: 5 | G6: 6 | H6: 7 | I6: 6 | J6: 5 | K6: 9 | L6: =SUM(C6:K6) -> 57
A7: =PAIRINGS!B32 -> Charlie Ward | B7: =PAIRINGS!D32 -> Crofton | C7: 6 | D7: 4 | E7: 5 | F7: 2 | G7: 5 | H7: 6 | I7: 6 | J7: 6 | K7: 6 | L7: =SUM(C7:K7) -> 46
A8: =PAIRINGS!B33 -> Nathan Reil | B8: =PAIRINGS!D33 -> Chesapeake | C8: 6 | D8: 4 | E8: 5 | F8: 4 | G8: 4 | H8: 4 | I8: 6 | J8: 4 | K8: 5 | L8: =SUM(C8:K8) -> 42
A9: =PAIRINGS!B34 -> Chris Mahnke | B9: =PAIRINGS!D34 -> Severn Run | C9: 7 | D9: 3 | E9: 4 | F9: 6 | G9: 5 | H9: 6 | I9: 7 | J9: 6 | K9: 7 | L9: =SUM(C9:K9) -> 51
A11: Name | B11: School | C11: 10 | D11: 11 | E11: 12 | F11: 13 | G11: 14 | H11: 15 | I11: 16 | J11: 17 | K11: 18 | L11: OUT | M11: TOTAL
A13: =A6 -> Evan Lyman | B13: =B6 -> Annapolis | C13: 5 | D13: 3 | I13: 8 | J13: 6 | K13: 6 | L13: =SUM(C13:K13) -> 28 | M13: =SUM(L6 + L13) -> 85
A14: =A7 -> Charlie Ward | B14: =B7 -> Crofton | C14: 5 | D14: 3 | I14: 6 | J14: 6 | K14: 3 | L14: =SUM(C14:K14) -> 23 | M14: =SUM(L7 + L14) -> 69
A15: =A8 -> Nathan Reil | B15: =B8 -> Chesapeake | C15: 5 | D15: 4 | I15: 6 | J15: 4 | K15: 5 | L15: =SUM(C15:K15) -> 24 | M15: =SUM(L8 + L15) -> 66
A16: =A9 -> Chris Mahnke | B16: =B9 -> Severn Run | C16: 5 | D16: 4 | I16: 6 | J16: 6 | K16: 5 | L16: =SUM(C16:K16) -> 26 | M16: =SUM(L9 + L16) -> 77

Sheet 15A
A1: Marshal | B1: Start | C1: AACPS County Championship 9/29 @ Compass Pointe LIVE SCORING
A2: =PAIRINGS!F35 -> Schmidt (GB) | B2: =PAIRINGS!A35 -> 15A
A4: Name | B4: School | C4: 1 | D4: 2 | E4: 3 | F4: 4 | G4: 5 | H4: 6 | I4: 7 | J4: 8 | K4: 9 | L4: IN
A6: =PAIRINGS!B35 -> Ethan Kelly | B6: =PAIRINGS!D35 -> Crofton | L6: =SUM(C6:K6) -> 0
A7: =PAIRINGS!B36 -> Mason Bombard | B7: =PAIRINGS!D36 -> Chesapeake | L7: =SUM(C7:K7) -> 0
A8: =PAIRINGS!B37 -> Aidan Pelkey | B8: =PAIRINGS!D37 -> Arundel | L8: =SUM(C8:K8) -> 0
A9: =PAIRINGS!B38 -> James Posey | B9: =PAIRINGS!D38 -> North County | L9: =SUM(C9:K9) -> 0
A11: Name | B11: School | C11: 10 | D11: 11 | E11: 12 | F11: 13 | G11: 14 | H11: 15 | I11: 16 | J11: 17 | K11: 18 | L11: OUT | M11: TOTAL
A13: =A6 -> Ethan Kelly | B13: =B6 -> Crofton | L13: =SUM(C13:K13) -> 0 | M13: =SUM(L6 + L13) -> 0
A14: =A7 -> Mason Bombard | B14: =B7 -> Chesapeake | L14: =SUM(C14:K14) -> 0 | M14: =SUM(L7 + L14) -> 0
A15: =A8 -> Aidan Pelkey | B15: =B8 -> Arundel | L15: =SUM(C15:K15) -> 0 | M15: =SUM(L8 + L15) -> 0
A16: =A9 -> James Posey | B16: =B9 -> North County | L16: =SUM(C16:K16) -> 0 | M16: =SUM(L9 + L16) -> 0

Sheet 15B
A1: Marshal | B1: Start | C1: AACPS County Championship 9/29 @ Compass Pointe LIVE SCORING
A2: =PAIRINGS!F39 -> Stimaker (BN) | B2: =PAIRINGS!A39 -> 15B
A4: Name | B4: School | C4: 1 | D4: 2 | E4: 3 | F4: 4 | G4: 5 | H4: 6 | I4: 7 | J4: 8 | K4: 9 | L4: IN
A6: =PAIRINGS!B39 -> Garrett James | B6: =PAIRINGS!D39 -> Severn Run | C6: 8 | D6: 4 | E6: 6 | F6: 4 | G6: 7 | H6: 9 | I6: 8 | J6: 7 | K6: 6 | L6: =SUM(C6:K6) -> 59
A7: =PAIRINGS!B40 -> Rhyan Arciaga | B7: =PAIRINGS!D40 -> Chesapeake Science | C7: 5 | D7: 4 | E7: 6 | F7: 6 | G7: 5 | H7: 6 | I7: 5 | J7: 10 | K7: 5 | L7: =SUM(C7:K7) -> 52
A8: =PAIRINGS!B41 -> Devin Crabbe | B8: =PAIRINGS!D41 -> Arundel | C8: 8 | D8: 6 | E8: 7 | F8: 8 | G8: 5 | H8: 10 | I8: 9 | J8: 13 | K8: 7 | L8: =SUM(C8:K8) -> 73
A9: =PAIRINGS!B42 -> Griffin Boritz | B9: =PAIRINGS!D42 -> North County | C9: 9 | D9: 4 | E9: 6 | F9: 5 | G9: 9 | H9: 6 | I9: 9 | J9: 9 | K9: 7 | L9: =SUM(C9:K9) -> 64
A11: Name | B11: School | C11: 10 | D11: 11 | E11: 12 | F11: 13 | G11: 14 | H11: 15 | I11: 16 | J11: 17 | K11: 18 | L11: OUT | M11: TOTAL
A13: =A6 -> Garrett James | B13: =B6 -> Severn Run | C13: 8 | D13: 6 | H13: 7 | I13: 12 | J13: 7 | K13: 6 | L13: =SUM(C13:K13) -> 46 | M13: =SUM(L6 + L13) -> 105
A14: =A7 -> Rhyan Arciaga | B14: =B7 -> Chesapeake Science | C14: 4 | D14: 3 | H14: 6 | I14: 7 | J14: 5 | K14: 5 | L14: =SUM(C14:K14) -> 30 | M14: =SUM(L7 + L14) -> 82
A15: =A8 -> Devin Crabbe | B15: =B8 -> Arundel | C15: 8 | D15: 6 | H15: 6 | I15: 13 | J15: 6 | K15: 5 | L15: =SUM(C15:K15) -> 44 | M15: =SUM(L8 + L15) -> 117
A16: =A9 -> Griffin Boritz | B16: =B9 -> North County | C16: 5 | D16: 5 | H16: 8 | I16: 8 | J16: 9 | K16: 6 | L16: =SUM(C16:K16) -> 41 | M16: =SUM(L9 + L16) -> 105

Sheet 14A
A1: Marshal | B1: Start | C1: AACPS County Championship 9/29 @ Compass Pointe LIVE SCORING
A2: =PAIRINGS!F43 -> McQuaid (CSP) | B2: =PAIRINGS!A43 -> 14A
A4: Name | B4: School | C4: 1 | D4: 2 | E4: 3 | F4: 4 | G4: 5 | H4: 6 | I4: 7 | J4: 8 | K4: 9 | L4: IN
A6: =PAIRINGS!B43 -> Kaden Wyatt | B6: =PAIRINGS!D43 -> Northeast | C6: 6 | D6: 4 | E6: 6 | F6: 6 | G6: 4 | H6: 4 | I6: 6 | J6: 5 | L6: =SUM(C6:K6) -> 41
A7: =PAIRINGS!B44 -> Cam Kellner | B7: =PAIRINGS!D44 -> Severn Run | C7: 6 | D7: 4 | E7: 5 | F7: 4 | G7: 6 | H7: 6 | I7: 7 | J7: 6 | L7: =SUM(C7:K7) -> 44
A8: =PAIRINGS!B45 -> Luke Gamble | B8: =PAIRINGS!D45 -> Arundel | C8: 9 | D8: 5 | E8: 7 | F8: 4 | G8: 7 | H8: 4 | I8: 6 | J8: 7 | L8: =SUM(C8:K8) -> 49
A9: =PAIRINGS!B46 -> Jaden Thompson | B9: =PAIRINGS!D46 -> South River | C9: 6 | D9: 6 | E9: 5 | F9: 7 | G9: 5 | H9: 5 | I9: 8 | J9: 5 | L9: =SUM(C9:K9) -> 47
A11: Name | B11: School | C11: 10 | D11: 11 | E11: 12 | F11: 13 | G11: 14 | H11: 15 | I11: 16 | J11: 17 | K11: 18 | L11: OUT | M11: TOTAL
G12: 6
A13: =A6 -> Kaden Wyatt | B13: =B6 -> Northeast | G13: 6 | H13: 3 | I13: 6 | J13: 5 | K13: 6 | L13: =SUM(C13:K13) -> 26 | M13: =SUM(L6 + L13) -> 67
A14: =A7 -> Cam Kellner | B14: =B7 -> Severn Run | G14: 8 | H14: 6 | I14: 8 | J14: 6 | K14: 5 | L14: =SUM(C14:K14) -> 33 | M14: =SUM(L7 + L14) -> 77
A15: Luke Gamble | B15: =B8 -> Arundel | G15: 5 | H15: 8 | I15: 7 | J15: 6 | K15: 6 | L15: =SUM(C15:K15) -> 32 | M15: =SUM(L8 + L15) -> 81
A16: =A9 -> Jaden Thompson | B16: =B9 -> South River | G16: 6 | H16: 5 | I16: 6 | J16: 5 | K16: 6 | L16: =SUM(C16:K16) -> 28 | M16: =SUM(L9 + L16) -> 75

Sheet 14B
B1: Start | C1: AACPS County Championship 9/29 @ Compass Pointe LIVE SCORING
A2: =PAIRINGS!F47 -> Martin (NE) | B2: =PAIRINGS!A47 -> 14B
A4: Name | B4: School | C4: 1 | D4: 2 | E4: 3 | F4: 4 | G4: 5 | H4: 6 | I4: 7 | J4: 8 | K4: 9 | L4: IN
A6: =PAIRINGS!B47 -> Drew Shallcross | B6: =PAIRINGS!D47 -> Annapolis | C6: 8 | D6: 5 | E6: 7 | F6: 4 | G6: 4 | H6: 6 | I6: 5 | J6: 5 | L6: =SUM(C6:K6) -> 44
A7: =PAIRINGS!B48 -> Liam Hontz | B7: =PAIRINGS!D48 -> North County | C7: 9 | D7: 3 | E7: 5 | F7: 4 | G7: 6 | H7: 5 | I7: 5 | J7: 5 | L7: =SUM(C7:K7) -> 42
A8: =PAIRINGS!B49 -> Reece Miguel | B8: =PAIRINGS!D49 -> Severn Run | C8: 9 | D8: 5 | E8: 4 | F8: 4 | G8: 5 | H8: 6 | I8: 8 | J8: 5 | L8: =SUM(C8:K8) -> 46
A9: =PAIRINGS!B50 -> Maxwell Morgan | B9: =PAIRINGS!D50 -> Arundel | C9: 8 | D9: 4 | E9: 9 | F9: 5 | G9: 6 | H9: 6 | I9: 7 | J9: 7 | L9: =SUM(C9:K9) -> 52
A11: Name | B11: School | C11: 10 | D11: 11 | E11: 12 | F11: 13 | G11: 14 | H11: 15 | I11: 16 | J11: 17 | K11: 18 | L11: OUT | M11: TOTAL
G12: 6
A13: =A6 -> Drew Shallcross | B13: =B6 -> Annapolis | G13: 6 | H13: 6 | I13: 8 | J13: 6 | K13: 9 | L13: =SUM(C13:K13) -> 35 | M13: =SUM(L6 + L13) -> 79
A14: =A7 -> Liam Hontz | B14: =B7 -> North County | G14: 6 | H14: 5 | I14: 7 | J14: 5 | K14: 7 | L14: =SUM(C14:K14) -> 30 | M14: =SUM(L7 + L14) -> 72
A15: =A8 -> Reece Miguel | B15: =B8 -> Severn Run | G15: 8 | H15: 6 | I15: 7 | J15: 8 | K15: 6 | L15: =SUM(C15:K15) -> 35 | M15: =SUM(L8 + L15) -> 81
A16: =A9 -> Maxwell Morgan | B16: =B9 -> Arundel | G16: 8 | H16: 4 | I16: 7 | J16: 6 | K16: 9 | L16: =SUM(C16:K16) -> 34 | M16: =SUM(L9 + L16) -> 86
H17: (H10:H16)

Sheet 10A
A1: Marshal | B1: Start | C1: AACPS County Championship 9/29 @ Compass Pointe LIVE SCORING
A2: =PAIRINGS!F52 -> White (CH) | B2: =PAIRINGS!A52 -> 10A
A4: Name | B4: School | C4: 1 | D4: 2 | E4: 3 | F4: 4 | G4: 5 | H4: 6 | I4: 7 | J4: 8 | K4: 9 | L4: IN
A6: =PAIRINGS!B52 -> Caroline Viscardi | B6: =PAIRINGS!D52 -> Broadneck | C6: 6 | D6: 5 | E6: 5 | F6: 5 | G6: 3 | H6: 6 | I6: 6 | L6: =SUM(C6:K6) -> 36
A7: =PAIRINGS!B53 -> Sarah Valencia | B7: =PAIRINGS!D53 -> South River | C7: 7 | D7: 3 | E7: 5 | F7: 4 | G7: 3 | H7: 4 | I7: 6 | L7: =SUM(C7:K7) -> 32
A8: =PAIRINGS!B54 -> Ava Shay | B8: =PAIRINGS!D54 -> Arundel | C8: 8 | D8: 3 | E8: 8 | F8: 3 | G8: 6 | H8: 6 | I8: 8 | L8: =SUM(C8:K8) -> 42
A9: =PAIRINGS!B55 -> Marissa Liverpool | B9: =PAIRINGS!D55 -> Crofton | C9: 5 | D9: 4 | E9: 6 | F9: 4 | G9: 5 | H9: 5 | I9: 8 | L9: =SUM(C9:K9) -> 37
A11: Name | B11: School | C11: 10 | D11: 11 | E11: 12 | F11: 13 | G11: 14 | H11: 15 | I11: 16 | J11: 17 | K11: 18 | L11: OUT | M11: TOTAL
A13: =A6 -> Caroline Viscardi | B13: =B6 -> Broadneck | C13: 4 | D13: 3 | E13: 6 | F13: 3 | G13: 6 | H13: 4 | I13: 8 | J13: 4 | K13: 5 | L13: =SUM(C13:K13) -> 43 | M13: =SUM(L6 + L13) -> 79
A14: =A7 -> Sarah Valencia | B14: =B7 -> South River | C14: 5 | D14: 3 | E14: 7 | F14: 5 | G14: 6 | H14: 4 | I14: 7 | J14: 5 | K14: 4 | L14: =SUM(C14:K14) -> 46 | M14: =SUM(L7 + L14) -> 78
A15: =A8 -> Ava Shay | B15: =B8 -> Arundel | C15: 5 | D15: 3 | E15: 8 | F15: 4 | G15: 6 | H15: 5 | I15: 8 | J15: 6 | K15: 6 | L15: =SUM(C15:K15) -> 51 | M15: =SUM(L8 + L15) -> 93
A16: =A9 -> Marissa Liverpool | B16: =B9 -> Crofton | C16: 7 | D16: 6 | E16: 6 | F16: 4 | G16: 7 | H16: 7 | I16: 8 | J16: 6 | K16: 8 | L16: =SUM(C16:K16) -> 59 | M16: =SUM(L9 + L16) -> 96

Sheet 10B
A1: Marshal | B1: Start | C1: AACPS County Championship 9/29 @ Compass Pointe LIVE SCORING
A2: =PAIRINGS!F56 -> Gardner (BN) | B2: =PAIRINGS!A56 -> 10B
A4: Name | B4: School | C4: 1 | D4: 2 | E4: 3 | F4: 4 | G4: 5 | H4: 6 | I4: 7 | J4: 8 | K4: 9 | L4: IN
A6: =PAIRINGS!B56 -> Audrey Nicely | B6: =PAIRINGS!D56 -> South River | C6: 6 | D6: 3 | E6: 5 | F6: 4 | G6: 7 | H6: 7 | I6: 9 | L6: =SUM(C6:K6) -> 41
A7: =PAIRINGS!B57 -> Paige Morgan | B7: =PAIRINGS!D57 -> Arundel | C7: 7 | D7: 6 | E7: 8 | F7: 4 | G7: 8 | H7: 7 | I7: 9 | L7: =SUM(C7:K7) -> 49
A8: =PAIRINGS!B58 -> Claire Kerley | B8: =PAIRINGS!D58 -> Crofton | C8: 12 | D8: 4 | E8: 7 | F8: 5 | G8: 4 | H8: 4 | I8: 6 | L8: =SUM(C8:K8) -> 42
A9: =PAIRINGS!B59 -> Zoe Port | B9: =PAIRINGS!D59 -> Severna Park | C9: 7 | D9: 3 | E9: 6 | F9: 6 | G9: 6 | H9: 7 | I9: 8 | L9: =SUM(C9:K9) -> 43
A11: Name | B11: School | C11: 10 | D11: 11 | E11: 12 | F11: 13 | G11: 14 | H11: 15 | I11: 16 | J11: 17 | K11: 18 | L11: OUT | M11: TOTAL
A13: =A6 -> Audrey Nicely | B13: =B6 -> South River | C13: 6 | D13: 4 | E13: 6 | F13: 4 | G13: 6 | H13: 3 | I13: 10 | J13: 5 | K13: 5 | L13: =SUM(C13:K13) -> 49 | M13: =SUM(L6 + L13) -> 90
A14: =A7 -> Paige Morgan | B14: =B7 -> Arundel | C14: 6 | D14: 3 | E14: 8 | F14: 6 | G14: 7 | H14: 6 | I14: 9 | J14: 8 | K14: 6 | L14: =SUM(C14:K14) -> 59 | M14: =SUM(L7 + L14) -> 108
A15: =A8 -> Claire Kerley | B15: =B8 -> Crofton | C15: 11 | D15: 10 | E15: 9 | F15: 6 | G15: 7 | H15: 6 | I15: 7 | J15: 4 | K15: 5 | L15: =SUM(C15:K15) -> 65 | M15: =SUM(L8 + L15) -> 107
A16: =A9 -> Zoe Port | B16: =B9 -> Severna Park | C16: 6 | D16: 7 | E16: 10 | F16: 12 | G16: 7 | H16: 4 | I16: 7 | J16: 8 | K16: 7 | L16: =SUM(C16:K16) -> 68 | M16: =SUM(L9 + L16) -> 111

Sheet 9A
A1: Marshal | B1: Start | C1: AACPS County Championship 9/29 @ Compass Pointe LIVE SCORING
A2: =PAIRINGS!F60 -> Caruso (SRN) | B2: =PAIRINGS!A60 -> 9A
A4: Name | B4: School | C4: 1 | D4: 2 | E4: 3 | F4: 4 | G4: 5 | H4: 6 | I4: 7 | J4: 8 | K4: 9 | L4: IN
A6: =PAIRINGS!B60 -> Lila Pietromica | B6: =PAIRINGS!D60 -> Broadneck | C6: 8 | D6: 8 | E6: 7 | F6: 5 | G6: 9 | H6: 6 | K6: 7 | L6: =SUM(C6:K6) -> 50
A7: =PAIRINGS!B61 -> Lizzy Thibodeau | B7: =PAIRINGS!D61 -> Annapolis | C7: 8 | D7: 8 | E7: 6 | F7: 3 | G7: 5 | H7: 6 | K7: 6 | L7: =SUM(C7:K7) -> 42
A8: =PAIRINGS!B62 -> Reagan Norfolk | B8: =PAIRINGS!D62 -> Southern | C8: 7 | D8: 5 | E8: 9 | F8: 5 | G8: 6 | H8: 6 | K8: 8 | L8: =SUM(C8:K8) -> 46
A9: =PAIRINGS!B63 -> Molly Boyle | B9: =PAIRINGS!D63 -> Crofton | C9: 8 | D9: 4 | E9: 7 | F9: 7 | G9: 7 | H9: 9 | K9: 7 | L9: =SUM(C9:K9) -> 49
E10: 55
A11: Name | B11: School | C11: 10 | D11: 11 | E11: 12 | F11: 13 | G11: 14 | H11: 15 | I11: 16 | J11: 17 | K11: 18 | L11: OUT | M11: TOTAL
K12: 5
A13: =A6 -> Lila Pietromica | B13: =B6 -> Broadneck | C13: 8 | D13: 4 | E13: 8 | F13: 6 | G13: 8 | H13: 6 | I13: 7 | J13: 9 | K13: 4 | L13: =SUM(C13:K13) -> 60 | M13: =SUM(L6 + L13) -> 110
A14: =A7 -> Lizzy Thibodeau | B14: =B7 -> Annapolis | C14: 7 | D14: 3 | E14: 7 | F14: 5 | G14: 7 | H14: 5 | I14: 7 | J14: 4 | K14: 6 | L14: =SUM(C14:K14) -> 51 | M14: =SUM(L7 + L14) -> 93
A15: =A8 -> Reagan Norfolk | B15: =B8 -> Southern | C15: 6 | D15: 4 | E15: 8 | F15: 5 | G15: 7 | H15: 5 | I15: 8 | J15: 5 | K15: 6 | L15: =SUM(C15:K15) -> 54 | M15: =SUM(L8 + L15) -> 100
A16: =A9 -> Molly Boyle | B16: =B9 -> Crofton | C16: 8 | D16: 8 | E16: 7 | F16: 4 | G16: 6 | H16: 5 | I16: 8 | J16: 4 | K16: 7 | L16: =SUM(C16:K16) -> 57 | M16: =SUM(L9 + L16) -> 106

Sheet 9B
A1: Marshal | B1: Start | C1: AACPS County Championship 9/29 @ Compass Pointe LIVE SCORING
A2: =PAIRINGS!F64 -> Harvan (CR) | B2: =PAIRINGS!A64 -> 9B
A4: Name | B4: School | C4: 1 | D4: 2 | E4: 3 | F4: 4 | G4: 5 | H4: 6 | I4: 7 | J4: 8 | K4: 9 | L4: IN
A6: =PAIRINGS!B64 -> Natalie Coe | B6: =PAIRINGS!D64 -> Broadneck | C6: 12 | D6: 5 | E6: 6 | F6: 3 | G6: 8 | H6: 6 | K6: 5 | L6: =SUM(C6:K6) -> 45
A7: =PAIRINGS!B65 -> Lauren Finn | B7: =PAIRINGS!D65 -> South River | C7: 10 | D7: 6 | E7: 8 | F7: 5 | G7: 6 | H7: 6 | K7: 8 | L7: =SUM(C7:K7) -> 49
A8: Bryan Calicoat | B8: Chesapeake | C8: 12 | D8: 6 | E8: 5 | F8: 4 | G8: 6 | H8: 8 | K8: 5 | L8: =SUM(C8:K8) -> 46
A9: =PAIRINGS!B67 | B9: =PAIRINGS!D67 | L9: =SUM(C9:K9) -> 0
A11: Name | B11: School | C11: 10 | D11: 11 | E11: 12 | F11: 13 | G11: 14 | H11: 15 | I11: 16 | J11: 17 | K11: 18 | L11: OUT | M11: TOTAL
A13: =A6 -> Natalie Coe | B13: =B6 -> Broadneck | C13: 3 | D13: 4 | E13: 8 | F13: 4 | G13: 9 | H13: 5 | I13: 9 | J13: 7 | K13: 5 | L13: =SUM(C13:K13) -> 54 | M13: =SUM(L6 + L13) -> 99
A14: =A7 -> Lauren Finn | B14: =B7 -> South River | C14: 6 | D14: 5 | E14: 7 | F14: 5 | G14: 8 | H14: 5 | I14: 10 | J14: 5 | K14: 8 | L14: =SUM(C14:K14) -> 59 | M14: =SUM(L7 + L14) -> 108
A15: =A8 -> Bryan Calicoat | B15: =B8 -> Chesapeake | C15: 7 | D15: 4 | E15: 6 | F15: 4 | G15: 8 | H15: 6 | I15: 10 | J15: 8 | K15: 7 | L15: =SUM(C15:K15) -> 60 | M15: =SUM(L8 + L15) -> 106
A16: =A9 | B16: =B9 | L16: =SUM(C16:K16) -> 0 | M16: =SUM(L9 + L16) -> 0

Sheet 8A
A1: Marshal | B1: Start | C1: AACPS County Championship 9/29 @ Compass Pointe LIVE SCORING
A2: =PAIRINGS!F68 -> Nathan (NC) | B2: =PAIRINGS!A68 -> 8A
A4: Name | B4: School | C4: 1 | D4: 2 | E4: 3 | F4: 4 | G4: 5 | H4: 6 | I4: 7 | J4: 8 | K4: 9 | L4: IN
F5: 4
A6: =PAIRINGS!B68 -> Claire Pierpoint | B6: =PAIRINGS!D68 -> Broadneck | J6: 6 | K6: 5 | L6: =SUM(C6:K6) -> 11
A7: =PAIRINGS!B69 -> Emily Huus | B7: =PAIRINGS!D69 -> Crofton | J7: 6 | K7: 8 | L7: =SUM(C7:K7) -> 14
A8: =PAIRINGS!B70 -> Elizabeth Schlossberg | B8: =PAIRINGS!D70 -> South River | J8: 10 | K8: 9 | L8: =SUM(C8:K8) -> 19
A9: =PAIRINGS!B71 | B9: =PAIRINGS!D71 | L9: =SUM(C9:K9) -> 0
A11: Name | B11: School | C11: 10 | D11: 11 | E11: 12 | F11: 13 | G11: 14 | H11: 15 | I11: 16 | J11: 17 | K11: 18 | L11: OUT | M11: TOTAL
A13: =A6 -> Claire Pierpoint | B13: =B6 -> Broadneck | C13: 6 | D13: 4 | E13: 9 | F13: 4 | G13: 11 | H13: 6 | I13: 8 | J13: 7 | L13: =SUM(C13:K13) -> 55 | M13: =SUM(L6 + L13) -> 66
A14: =A7 -> Emily Huus | B14: =B7 -> Crofton | C14: 7 | D14: 3 | E14: 9 | F14: 5 | G14: 7 | H14: 6 | I14: 10 | J14: 7 | L14: =SUM(C14:K14) -> 54 | M14: =SUM(L7 + L14) -> 68
A15: =A8 -> Elizabeth Schlossberg | B15: =B8 -> South River | C15: 9 | D15: 3 | E15: 8 | F15: 5 | G15: 6 | H15: 6 | I15: 9 | J15: 5 | L15: =SUM(C15:K15) -> 51 | M15: =SUM(L8 + L15) -> 70
A16: =A9 | B16: =B9 | L16: =SUM(C16:K16) -> 0 | M16: =SUM(L9 + L16) -> 0

Sheet 8B
A1: Marshal | B1: Start | C1: AACPS County Championship 9/29 @ Compass Pointe LIVE SCORING
A2: =PAIRINGS!F72 | B2: =PAIRINGS!A72 -> 8B
A4: Name | B4: School | C4: 1 | D4: 2 | E4: 3 | F4: 4 | G4: 5 | H4: 6 | I4: 7 | J4: 8 | K4: 9 | L4: IN
A6: =PAIRINGS!B72 | B6: =PAIRINGS!D72 | L6: =SUM(C6:K6) -> 0
A7: =PAIRINGS!B73 | B7: =PAIRINGS!D73 | L7: =SUM(C7:K7) -> 0
A8: =PAIRINGS!B74 | B8: =PAIRINGS!D74 | L8: =SUM(C8:K8) -> 0
A9: =PAIRINGS!B75 | B9: =PAIRINGS!D75 | L9: =SUM(C9:K9) -> 0
A11: Name | B11: School | C11: 10 | D11: 11 | E11: 12 | F11: 13 | G11: 14 | H11: 15 | I11: 16 | J11: 17 | K11: 18 | L11: OUT | M11: TOTAL
A13: =A6 | B13: =B6 | L13: =SUM(C13:K13) -> 0 | M13: =SUM(L6 + L13) -> 0
A14: =A7 | B14: =B7 | L14: =SUM(C14:K14) -> 0 | M14: =SUM(L7 + L14) -> 0
A15: =A8 | B15: =B8 | L15: =SUM(C15:K15) -> 0 | M15: =SUM(L8 + L15) -> 0
A16: =A9 | B16: =B9 | L16: =SUM(C16:K16) -> 0 | M16: =SUM(L9 + L16) -> 0

Sheet 7A
A1: Marshal | B1: Start | C1: AACPS County Championship 9/29 @ Compass Pointe LIVE SCORING
A2: =PAIRINGS!F76 -> Campbell (CH) | B2: =PAIRINGS!A76 -> 7A
A4: Name | B4: School | C4: 1 | D4: 2 | E4: 3 | F4: 4 | G4: 5 | H4: 6 | I4: 7 | J4: 8 | K4: 9 | L4: IN
A6: =PAIRINGS!B76 -> Daniel Capo | B6: =PAIRINGS!D76 -> Annapolis | C6: 8 | D6: 4 | E6: 10 | I6: 12 | J6: 13 | K6: 8 | L6: =SUM(C6:K6) -> 55
A7: =PAIRINGS!B77 -> Ethan Price | B7: =PAIRINGS!D77 -> North County | C7: 7 | D7: 3 | E7: 7 | I7: 8 | J7: 6 | K7: 6 | L7: =SUM(C7:K7) -> 37
A8: =PAIRINGS!B78 -> Connor Giest | B8: =PAIRINGS!D78 -> Severn Run | C8: 9 | D8: 4 | E8: 8 | I8: 10 | J8: 7 | K8: 6 | L8: =SUM(C8:K8) -> 44
A9: =PAIRINGS!B79 -> Mason Kolodziejski | B9: =PAIRINGS!D79 -> Northeast | C9: 6 | D9: 8 | E9: 6 | I9: 10 | J9: 7 | K9: 5 | L9: =SUM(C9:K9) -> 42
A11: Name | B11: School | C11: 10 | D11: 11 | E11: 12 | F11: 13 | G11: 14 | H11: 15 | I11: 16 | J11: 17 | K11: 18 | L11: OUT | M11: TOTAL
A13: =A6 -> Daniel Capo | B13: =B6 -> Annapolis | C13: 7 | D13: 9 | E13: 12 | F13: 7 | G13: 9 | H13: 5 | I13: 12 | J13: 7 | K13: 5 | L13: =SUM(C13:K13) -> 73 | M13: =SUM(L6 + L13) -> 128
A14: =A7 -> Ethan Price | B14: =B7 -> North County | C14: 4 | D14: 3 | E14: 7 | F14: 3 | G14: 9 | H14: 5 | I14: 8 | J14: 6 | K14: 5 | L14: =SUM(C14:K14) -> 50 | M14: =SUM(L7 + L14) -> 87
A15: =A8 -> Connor Giest | B15: =B8 -> Severn Run | C15: 10 | D15: 4 | E15: 9 | F15: 3 | G15: 6 | H15: 5 | I15: 7 | J15: 9 | K15: 7 | L15: =SUM(C15:K15) -> 60 | M15: =SUM(L8 + L15) -> 104
A16: =A9 -> Mason Kolodziejski | B16: =B9 -> Northeast | C16: 5 | D16: 4 | E16: 8 | F16: 5 | G16: 6 | H16: 5 | I16: 7 | J16: 5 | K16: 5 | L16: =SUM(C16:K16) -> 50 | M16: =SUM(L9 + L16) -> 92

Sheet 7B
A1: Marshal | B1: Start | C1: AACPS County Championship 9/29 @ Compass Pointe LIVE SCORING
A2: =PAIRINGS!F80 -> K Dean (SP) | B2: =PAIRINGS!A80 -> 7B
A4: Name | B4: School | C4: 1 | D4: 2 | E4: 3 | F4: 4 | G4: 5 | H4: 6 | I4: 7 | J4: 8 | K4: 9 | L4: IN
A6: =PAIRINGS!B80 -> Alec Behegan | B6: =PAIRINGS!D80 -> North County | C6: 8 | D6: 4 | I6: 8 | J6: 8 | K6: 6 | L6: =SUM(C6:K6) -> 34
A7: =PAIRINGS!B81 -> Dylan Morgan | B7: =PAIRINGS!D81 -> Chesapeake Science | C7: 8 | D7: 4 | I7: 6 | J7: 9 | K7: 6 | L7: =SUM(C7:K7) -> 33
A8: =PAIRINGS!B82 -> Brandon Rochon | B8: =PAIRINGS!D82 -> Severn Run | C8: 8 | D8: 4 | I8: 8 | J8: 5 | K8: 5 | L8: =SUM(C8:K8) -> 30
A9: =PAIRINGS!B83 -> Ethan Berry | B9: =PAIRINGS!D83 -> South River | C9: 6 | D9: 4 | I9: 7 | J9: 6 | K9: 5 | L9: =SUM(C9:K9) -> 28
A11: Name | B11: School | C11: 10 | D11: 11 | E11: 12 | F11: 13 | G11: 14 | H11: 15 | I11: 16 | J11: 17 | K11: 18 | L11: OUT | M11: TOTAL
A13: =A6 -> Alec Behegan | B13: =B6 -> North County | C13: 5 | D13: 5 | E13: 7 | F13: 5 | G13: 11 | H13: 5 | I13: 6 | J13: 5 | K13: 5 | L13: =SUM(C13:K13) -> 54 | M13: =SUM(L6 + L13) -> 88
A14: =A7 -> Dylan Morgan | B14: =B7 -> Chesapeake Science | C14: 6 | D14: 4 | E14: 7 | F14: 3 | G14: 7 | H14: 6 | I14: 8 | J14: 6 | K14: 5 | L14: =SUM(C14:K14) -> 52 | M14: =SUM(L7 + L14) -> 85
A15: =A8 -> Brandon Rochon | B15: =B8 -> Severn Run | C15: 5 | D15: 4 | E15: 6 | F15: 4 | G15: 4 | H15: 3 | I15: 8 | J15: 5 | K15: 7 | L15: =SUM(C15:K15) -> 46 | M15: =SUM(L8 + L15) -> 76
A16: =A9 -> Ethan Berry | B16: =B9 -> South River | C16: 6 | D16: 5 | E16: 9 | F16: 6 | G16: 9 | H16: 5 | I16: 7 | J16: 7 | K16: 7 | L16: =SUM(C16:K16) -> 61 | M16: =SUM(L9 + L16) -> 89

Sheet 6A
A1: Marshal | B1: Start | C1: AACPS County Championship 9/29 @ Compass Pointe LIVE SCORING
A2: =PAIRINGS!F84 -> Fein (SRN) | B2: =PAIRINGS!A84 -> 6A
A4: Name | B4: School | C4: 1 | D4: 2 | E4: 3 | F4: 4 | G4: 5 | H4: 6 | I4: 7 | J4: 8 | K4: 9 | L4: IN
A6: =PAIRINGS!B84 -> Nate Alimo | B6: =PAIRINGS!D84 -> North County | C6: 7 | H6: 7 | I6: 8 | J6: 5 | K6: 6 | L6: =SUM(C6:K6) -> 33
A7: =PAIRINGS!B85 -> Jack Smith | B7: =PAIRINGS!D85 -> Broadneck | C7: 5 | H7: 5 | I7: 5 | J7: 8 | K7: 6 | L7: =SUM(C7:K7) -> 29
A8: =PAIRINGS!B86 -> Ethan Goughenour | B8: =PAIRINGS!D86 -> Old Mill | C8: 8 | H8: 6 | I8: 11 | J8: 8 | K8: 8 | L8: =SUM(C8:K8) -> 41
A9: =PAIRINGS!B87 -> Brooks Bailey | B9: =PAIRINGS!D87 -> South River | C9: 6 | H9: 7 | I9: 7 | J9: 4 | K9: 5 | L9: =SUM(C9:K9) -> 29
A11: Name | B11: School | C11: 10 | D11: 11 | E11: 12 | F11: 13 | G11: 14 | H11: 15 | I11: 16 | J11: 17 | K11: 18 | L11: OUT | M11: TOTAL
A13: =A6 -> Nate Alimo | B13: =B6 -> North County | C13: 4 | D13: 5 | E13: 6 | F13: 8 | G13: 7 | H13: 5 | I13: 8 | J13: 6 | K13: 5 | L13: =SUM(C13:K13) -> 54 | M13: =SUM(L6 + L13) -> 87
A14: =A7 -> Jack Smith | B14: =B7 -> Broadneck | C14: 5 | D14: 4 | E14: 5 | F14: 4 | G14: 6 | H14: 5 | I14: 6 | J14: 4 | K14: 5 | L14: =SUM(C14:K14) -> 44 | M14: =SUM(L7 + L14) -> 73
A15: =A8 -> Ethan Goughenour | B15: =B8 -> Old Mill | C15: 3 | D15: 5 | E15: 7 | F15: 5 | G15: 6 | H15: 7 | I15: 11 | J15: 8 | K15: 6 | L15: =SUM(C15:K15) -> 58 | M15: =SUM(L8 + L15) -> 99
A16: =A9 -> Brooks Bailey | B16: =B9 -> South River | C16: 5 | D16: 5 | E16: 5 | F16: 3 | G16: 6 | H16: 5 | I16: 6 | J16: 5 | K16: 4 | L16: =SUM(C16:K16) -> 44 | M16: =SUM(L9 + L16) -> 73
D17: 5

Sheet 6B
A1: Marshal | B1: Start | C1: AACPS County Championship 9/29 @ Compass Pointe LIVE SCORING
A2: =PAIRINGS!F88 -> Shay (AR) | B2: =PAIRINGS!A88 -> 6B
A4: Name | B4: School | C4: 1 | D4: 2 | E4: 3 | F4: 4 | G4: 5 | H4: 6 | I4: 7 | J4: 8 | K4: 9 | L4: IN
A6: =PAIRINGS!B88 -> Devon Myers | B6: =PAIRINGS!D88 -> Glen Burnie | H6: 8 | I6: 9 | J6: 8 | K6: 4 | L6: =SUM(C6:K6) -> 29
A7: =PAIRINGS!B89 -> Alex Kapikian | B7: =PAIRINGS!D89 -> Broadneck | H7: 7 | I7: 6 | J7: 6 | K7: 5 | L7: =SUM(C7:K7) -> 24
A8: =PAIRINGS!B90 | B8: =PAIRINGS!D90 | L8: =SUM(C8:K8) -> 0
A9: =PAIRINGS!B91 | B9: =PAIRINGS!D91 | L9: =SUM(C9:K9) -> 0
A11: Name | B11: School | C11: 10 | D11: 11 | E11: 12 | F11: 13 | G11: 14 | H11: 15 | I11: 16 | J11: 17 | K11: 18 | L11: OUT | M11: TOTAL
A13: =A6 -> Devon Myers | B13: =B6 -> Glen Burnie | C13: 6 | D13: 6 | E13: 7 | F13: 5 | G13: 9 | H13: 5 | I13: 8 | J13: 9 | K13: 8 | L13: =SUM(C13:K13) -> 63 | M13: =SUM(L6 + L13) -> 92
A14: =A7 -> Alex Kapikian | B14: =B7 -> Broadneck | C14: 5 | D14: 5 | E14: 6 | F14: 4 | G14: 4 | H14: 5 | I14: 5 | J14: 5 | K14: 4 | L14: =SUM(C14:K14) -> 43 | M14: =SUM(L7 + L14) -> 67
A15: =A8 | B15: =B8 | L15: =SUM(C15:K15) -> 0 | M15: =SUM(L8 + L15) -> 0
A16: =A9 | B16: =B9 | L16: =SUM(C16:K16) -> 0 | M16: =SUM(L9 + L16) -> 0

Sheet RESULTS
A1: County Championships 9/29 @ Compass Pointe 8:30am RESULTS | F1: LEADERBOARD | I1: LEADERBOARD
A2: First and Last Name | B2: Grade | C2: School | D2: M/F | E2: Score | F2: Place | G2: Name/School | H2: Score | I2: Place | J2: Name/School | K2: Score
A3: William Meyer | B3: 11 | C3: Annapolis | D3: M | E3: ='17B'!M16 -> 74 | G3: =A33 -> Ty Swann | H3: =E33 -> 67 | J3: =A22 -> Caroline Viscardi | K3: =E22 -> 79
A4: Evan Lyman | B4: 11 | C4: Annapolis | D4: M | E4: ='16B'!M13 -> 85 | G4: =A61 -> Davis Balderston | H4: =E61 -> 63 | J4: =A69 -> Sarah Valencia | K4: =E69 -> 78
A5: Drew Shallcross | B5: 12 | C5: Annapolis | D5: M | E5: ='14B'!M13 -> 79 | G5: =A16 -> James Jonker | H5: =E16 -> 64 | J5: =A42 -> Emily Huus | K5: =E42 -> 68
A6: Daniel Capo | B6: 12 | C6: Annapolis | D6: M | E6: ='7A'!M13 -> 128 | G6: =A27 -> Alan Higgins | H6: =E27 -> 73 | J6: =A14 -> Ava Shay | K6: =E14 -> 93
A7: Colt Jett | B7: 12 | C7: Annapolis | D7: M | G7: =A28 -> Nathan Reil | H7: =E28 -> 66 | J7: =A23 -> Natalie Coe | K7: =E23 -> 99
A8: Lizzy Thibodeau | B8: 9 | C8: Annapolis | D8: F | E8: ='9A'!M14 -> 93 | G8: =A20 -> Alex Kapikian | H8: =E20 -> 67 | J8: =A25 -> Claire Pierpoint | K8: =E25 -> 66
A9: Chase Fortescue | B9: 12 | C9: Arundel | D9: M | E9: ='18B'!M14 -> 76 | G9: =A77 -> Ewan Ivey | H9: =E77 -> 66 | J9: =A39 -> Marissa Liverpool | K9: =E39 -> 96
A10: Aidan Pelkey | B10: 11 | C10: Arundel | D10: M | E10: ='15A'!M15 -> 0 | G10: =A62 -> Chase Connell | H10: =E62 -> 60 | J10: =A75 -> Elizabeth Schlossberg | K10: =E75 -> 70
A11: Devin Crabbe | B11: 11 | C11: Arundel | D11: M | E11: ='15B'!M15 -> 117 | G11: =A36 -> Charlie Ward | H11: =E36 -> 69 | J11: =A74 -> Audrey Nicely | K11: =E74 -> 90
A12: Luke Gamble | B12: 12 | C12: Arundel | D12: M | E12: ='14A'!M15 -> 81 | G12: =A34 -> Ben Cunningham | H12: =E34 -> 73
A13: Maxwell Morgan | B13: 11 | C13: Arundel | D13: M | E13: ='14B'!M16 -> 86 | F13: TOP SCORES - TEAM
A14: Ava Shay | B14: 12 | C14: Arundel | D14: F | E14: ='10A'!M15 -> 93
A15: Paige Morgan | B15: 12 | C15: Arundel | D15: F | E15: ='10B'!M14 -> 108
A16: James Jonker | B16: 12 | C16: Broadneck | D16: M | E16: ='1A'!M15 -> 64 | F16: 1
A17: Michael Peterson | B17: 11 | C17: Broadneck | D17: M | E17: ='1B'!M15 -> 68 | F17: 2
A18: Micah Gossard | B18: 10 | C18: Broadneck | D18: M | E18: ='18A'!M13 -> 71 | F18: 3
A19: Max Harada | B19: 12 | C19: Broadneck | D19: M | E19: ='18B'!M13 -> 76 | F19: 4
A20: Alex Kapikian | B20: 11 | C20: Broadneck | D20: M | E20: ='6B'!M14 -> 67 | F20: 5
A21: Jack Smith | B21: 10 | C21: Broadneck | D21: M | E21: ='6A'!M14 -> 73 | F21: 6
A22: Caroline Viscardi | B22: 12 | C22: Broadneck | D22: F | E22: ='10A'!M13 -> 79 | F22: 7
A23: Natalie Coe | B23: 11 | C23: Broadneck | D23: F | E23: ='9B'!M13 -> 99 | F23: 8
A24: Lila Pietromica | B24: 11 | C24: Broadneck | D24: F | E24: ='9A'!M13 -> 110 | F24: 9
A25: Claire Pierpoint | B25: 9 | C25: Broadneck | D25: F | E25: ='8A'!M13 -> 66 | F25: 10
A26: Gavin Allison | B26: 12 | C26: Chesapeake | D26: M | E26: ='1A'!M16 -> 71
A27: Alan Higgins | B27: 12 | C27: Chesapeake | D27: M | E27: ='1B'!M16 -> 73 | F27: TOP SCORES - M
A28: Nathan Reil | B28: 12 | C28: Chesapeake | D28: M | E28: ='16B'!M15 -> 66
A29: Liam Finnegan | B29: 10 | C29: Chesapeake | D29: M | E29: ='17A'!M14 -> 75
A30: Cooper Barnes | B30: 12 | C30: Chesapeake | D30: M | E30: ='18B'!M16 -> 76 | F30: Place | G30: Name / School | H30: Score
A31: Mason Bombard | B31: 12 | C31: Chesapeake | D31: M | E31: ='15A'!M14 -> 0 | F31: 1
A32: Bryn Calicoat | B32: 11 | C32: Chesapeake | D32: F | E32: ='9B'!M15 -> 106 | F32: 2
A33: Ty Swann | B33: 11 | C33: Crofton | D33: M | E33: ='1A'!M13 -> 67 | F33: 3
A34: Ben Cunningham | B34: 12 | C34: Crofton | D34: M | E34: ='17A'!M15 -> 73 | F34: 4
A35: Gianni Gallow | B35: 12 | C35: Crofton | D35: M | E35: ='16A'!M14 -> 74 | F35: 5
A36: Charlie Ward | B36: 9 | C36: Crofton | D36: M | E36: ='16B'!M14 -> 69 | F36: 6
A37: Nate Fine | B37: 12 | C37: Crofton | D37: M | E37: ='17B'!M14 -> 75 | F37: 7
A38: Ethan Kelly | B38: 12 | C38: Crofton | D38: M | E38: ='15A'!M13 -> 0 | F38: 8
A39: Marissa Liverpool | B39: 11 | C39: Crofton | D39: F | E39: ='10A'!M16 -> 96 | F39: 9
A40: Claire Kerley | B40: 10 | C40: Crofton | D40: F | E40: ='10B'!M15 -> 107 | F40: 10
...
